Traceback (most recent call last):
  File "c:\users\ella metcalfe\anaconda3\envs\py37\lib\site-packages\jupyter_cache\executors\utils.py", line 56, in single_nb_execution
    record_timing=False,
  File "c:\users\ella metcalfe\anaconda3\envs\py37\lib\site-packages\nbclient\client.py", line 1204, in execute
    return NotebookClient(nb=nb, resources=resources, km=km, **kwargs).execute()
  File "c:\users\ella metcalfe\anaconda3\envs\py37\lib\site-packages\nbclient\util.py", line 84, in wrapped
    return just_run(coro(*args, **kwargs))
  File "c:\users\ella metcalfe\anaconda3\envs\py37\lib\site-packages\nbclient\util.py", line 62, in just_run
    return loop.run_until_complete(coro)
  File "c:\users\ella metcalfe\anaconda3\envs\py37\lib\asyncio\base_events.py", line 587, in run_until_complete
    return future.result()
  File "c:\users\ella metcalfe\anaconda3\envs\py37\lib\site-packages\nbclient\client.py", line 664, in async_execute
    cell, index, execution_count=self.code_cells_executed + 1
  File "c:\users\ella metcalfe\anaconda3\envs\py37\lib\site-packages\nbclient\client.py", line 965, in async_execute_cell
    await self._check_raise_for_error(cell, cell_index, exec_reply)
  File "c:\users\ella metcalfe\anaconda3\envs\py37\lib\site-packages\nbclient\client.py", line 862, in _check_raise_for_error
    raise CellExecutionError.from_cell_and_msg(cell, exec_reply_content)
nbclient.exceptions.CellExecutionError: An error occurred while executing the following cell:
------------------
from scipy.integrate import odeint

# Model definition
def pend(X,t,w,k):
  dxdt = X[1]
  dydt = -w**2*np.sin(X[0])-k*X[1]
  return [dxdt, dydt]

t0=0; X0=[1,0] #initial conditions for t,x,y
w=1; k=0

t = np.linspace(0,20,100)    # time points

# solve ODE
X = odeint(dXdt,X0,t,args=(w,k))

# plot results
fig,ax = plt.subplots(figsize=(8,4))
ax.plot(t,X[:,0],'b')
plt.ylabel('x')
plt.xlabel('time')
plt.xlim([0,20])
plt.show()
------------------

[1;31m---------------------------------------------------------------------------[0m
[1;31mNameError[0m                                 Traceback (most recent call last)
[1;32mC:\Users\ELLAME~1\AppData\Local\Temp/ipykernel_4272/1458885959.py[0m in [0;36m<module>[1;34m[0m
[0;32m     13[0m [1;33m[0m[0m
[0;32m     14[0m [1;31m# solve ODE[0m[1;33m[0m[1;33m[0m[1;33m[0m[0m
[1;32m---> 15[1;33m [0mX[0m [1;33m=[0m [0modeint[0m[1;33m([0m[0mdXdt[0m[1;33m,[0m[0mX0[0m[1;33m,[0m[0mt[0m[1;33m,[0m[0margs[0m[1;33m=[0m[1;33m([0m[0mw[0m[1;33m,[0m[0mk[0m[1;33m)[0m[1;33m)[0m[1;33m[0m[1;33m[0m[0m
[0m[0;32m     16[0m [1;33m[0m[0m
[0;32m     17[0m [1;31m# plot results[0m[1;33m[0m[1;33m[0m[1;33m[0m[0m

[1;31mNameError[0m: name 'dXdt' is not defined
NameError: name 'dXdt' is not defined

